Workbook
Name ExternalData_1: 'Q2 Raw Data'!$A$1:$L$7846

Sheet ReadME
A1: IE6600 Hackathon · Team 4 · Clean Energy Got Cheap. Did We Switch?
A2: Link to the sheet | B2: https://docs.google.com/spreadsheets/d/1r1fUgiDv_OyfrQAPSim_4NRRbJcSQJgECVBrS2IWZnY/edit?usp=sharing
A3: About This Workbook
A4: • | B4: This workbook holds the raw data, calculations (pivot tables and formulas) and charts behind our presentation.
A5: • | B5: Python charts were made in our Jupyter notebook from the raw-data tabs in this file and are pasted in as images.
A6: • | B6: Q1 Cost: How much have solar and wind costs fallen compared with coal and gas?
A7: • | B7: Q2 Mix: How fast has the electricity mix changed in the US and worldwide?
A8: • | B8: Q3 Pace: Which countries are switching away from fossil fuels fastest, and is the US among them?
A10: Organization & Structure
A11: • | B11: Each question has its own group of tabs, named as follows: Q# [content] (e.g. Q1 Raw data, Q1 IRENA Solar Pivot)
A12: • | B12: Within each question, tabs run in order: Raw data → Sources / Notes → Pivots & calculations → Excel charts → Python chart
A13: • | B13: Each chart has its written interpretation next to it on the same tab
A14: • | B14: "Slide #" in the tab guide below shows where each chart appears in the presentation
A16: Tab Guide
A17: • | B17: Q1 Raw data = cost of new electricity (US$/MWh): Lazard (US, nominal $) and IRENA (world + countries, real 2025 $)
A18: • | B18: Q1 IRENA 2025 Bar = pivot of 2025 cost, US vs world average; Excel chart (slide 3)
A19: • | B19: Q1 IRENA Solar Pivot / Q1 IRENA Wind Pivot = cost by year, US vs world; Excel charts (slide 4)
A20: • | B20: Q1 Lazard Pivot = US cost by technology and year (the Python version of this chart is on slide 3)
A21: • | B21: Q1 Python = Python charts: Lazard cost curve (slide 3) and IRENA country panels
A22: • | B22: Q2 Raw Data = share of electricity by source, 2000-2025; formula columns Other and Wind + Solar
A23: • | B23: Q2 Data Sources | Notes = dataset link, definitions and the 88-country median analysis
A24: • | B24: Q2 Electricity Mix = US mix every five years and the 100% stacked column chart (slide 5)
A25: • | B25: Q2 Python Chart = wind + solar share, US vs World (slide 5)
A26: • | B26: Q3 Raw Data = electricity shares in 2015 and 2024, cleaned; helper columns Solar_Wind_pct, Other_pct, Large_2024
A27: • | B27: Q3 Pivot / Q3 Table = fossil share 2015 vs 2024 with change and rank formulas; results sorted biggest fall first
A28: • | B28: Q3 Replacements = change in each source's share (what replaced fossil fuels)
... A30: • | B30: Python Graph = top 10 fastest switchers plus the US and World (slide 6)
A32: Color Key (chart palette, same on every chart and slide)
B33: Amber #E0A800 = solar & wind
B34: Gray #5A6573 = fossil fuels (coal, gas, oil)
B35: Purple #8E6CB4 = nuclear
B36: Blue #2C6FAC = hydro; World / global average in comparisons
B37: Navy #1E2A38 = United States highlight; titles and text
B38: Light gray #C5CAD0 = other sources; background bars
A40: Data Sources
A41: • | B41: Lazard LCOE+ v18.0 (June 2025): https://www.lazard.com/media/5tlbhyla/lazards-lcoeplus-june-2025-_vf.pdf#page=14
A42: • | B42: IRENA Renewable Power Generation Costs in 2025: https://www.irena.org/Publications/2026/Jul/Renewable-Power-Generation-Costs-in-2025
A43: • | B43: Our World in Data (Q2), share of electricity by source: https://ourworldindata.org/grapher/share-elec-by-source
A44: • | B44: Our World in Data (Q3), energy dataset, 2026 release: https://github.com/owid/energy-data
A46: Assumptions & Cleaning
...

Sheet Q1 Raw data
A1: Q1 raw data: cost of new electricity by technology
A2: US dollars per MWh (LCOE of new plants). Lazard (US, nominal $) has coal and gas; IRENA (world + countries, real 2025 $) covers renewables only. Blank = not covered by that source, not zero. Filter by Source before comparing.
A4: Source | B4: Region | C4: Region_type | D4: Year | E4: Dollar_basis | F4: Solar PV | G4: Onshore wind | H4: Coal | I4: Gas combined cycle | J4: Hydropower
A5: Lazard LCOE+ v18.0 (June 2025) | B5: United States | C5: Country | D5: 2009 | E5: Nominal USD | F5: 359 | G5: 135 | H5: 111 | I5: 83
A6: Lazard LCOE+ v18.0 (June 2025) | B6: United States | C6: Country | D6: 2010 | E6: Nominal USD | F6: 248 | G6: 124 | H6: 111 | I6: 82
A7: Lazard LCOE+ v18.0 (June 2025) | B7: United States | C7: Country | D7: 2011 | E7: Nominal USD | F7: 157 | G7: 71 | H7: 111 | I7: 83
A8: Lazard LCOE+ v18.0 (June 2025) | B8: United States | C8: Country | D8: 2012 | E8: Nominal USD | F8: 125 | G8: 72 | H8: 102 | I8: 75
A9: Lazard LCOE+ v18.0 (June 2025) | B9: United States | C9: Country | D9: 2013 | E9: Nominal USD | F9: 98 | G9: 70 | H9: 105 | I9: 74
A10: Lazard LCOE+ v18.0 (June 2025) | B10: United States | C10: Country | D10: 2014 | E10: Nominal USD | F10: 79 | G10: 59 | H10: 109 | I10: 74
A11: Lazard LCOE+ v18.0 (June 2025) | B11: United States | C11: Country | D11: 2015 | E11: Nominal USD | F11: 64 | G11: 55 | H11: 108 | I11: 65
A12: Lazard LCOE+ v18.0 (June 2025) | B12: United States | C12: Country | D12: 2016 | E12: Nominal USD | F12: 55 | G12: 47 | H12: 102 | I12: 63
A13: Lazard LCOE+ v18.0 (June 2025) | B13: United States | C13: Country | D13: 2017 | E13: Nominal USD | F13: 50 | G13: 45 | H13: 102 | I13: 60
A14: Lazard LCOE+ v18.0 (June 2025) | B14: United States | C14: Country | D14: 2018 | E14: Nominal USD | F14: 43 | G14: 42 | H14: 102 | I14: 58
A15: Lazard LCOE+ v18.0 (June 2025) | B15: United States | C15: Country | D15: 2019 | E15: Nominal USD | F15: 40 | G15: 41 | H15: 109 | I15: 56
A16: Lazard LCOE+ v18.0 (June 2025) | B16: United States | C16: Country | D16: 2020 | E16: Nominal USD | F16: 37 | G16: 40 | H16: 112 | I16: 59
... A20: Lazard LCOE+ v18.0 (June 2025) | B20: United States | C20: Country | D20: 2025 | E20: Nominal USD | F20: 58 | G20: 61 | H20: 122 | I20: 78
A21: IRENA (2026) Renewable Power Generation Costs in 2025 | B21: World | C21: Global average | D21: 2010 | E21: Real 2025 USD | F21: 407.7 | G21: 113.6 | J21: 43.7
A22: IRENA (2026) Renewable Power Generation Costs in 2025 | B22: World | C22: Global average | D22: 2011 | E22: Real 2025 USD | F22: 343.9 | G22: 107.7 | J22: 41.3
A23: IRENA (2026) Renewable Power Generation Costs in 2025 | B23: World | C23: Global average | D23: 2012 | E23: Real 2025 USD | F23: 259.8 | G23: 98.8 | J23: 41.4
A24: IRENA (2026) Renewable Power Generation Costs in 2025 | B24: World | C24: Global average | D24: 2013 | E24: Real 2025 USD | F24: 202.6 | G24: 99.1 | J24: 47
A25: IRENA (2026) Renewable Power Generation Costs in 2025 | B25: World | C25: Global average | D25: 2014 | E25: Real 2025 USD | F25: 180.8 | G25: 87.6 | J25: 37.3
A26: IRENA (2026) Renewable Power Generation Costs in 2025 | B26: World | C26: Global average | D26: 2015 | E26: Real 2025 USD | F26: 133.7 | G26: 76 | J26: 41.4
A27: IRENA (2026) Renewable Power Generation Costs in 2025 | B27: World | C27: Global average | D27: 2016 | E27: Real 2025 USD | F27: 117.4 | G27: 69.8 | J27: 54.4
A28: IRENA (2026) Renewable Power Generation Costs in 2025 | B28: World | C28: Global average | D28: 2017 | E28: Real 2025 USD | F28: 93.6 | G28: 64.8 | J28: 56.1
A29: IRENA (2026) Renewable Power Generation Costs in 2025 | B29: World | C29: Global average | D29: 2018 | E29: Real 2025 USD | F29: 79.2 | G29: 55.6 | J29: 46.3
A30: IRENA (2026) Renewable Power Generation Costs in 2025 | B30: World | C30: Global average | D30: 2019 | E30: Real 2025 USD | F30: 68.5 | G30: 49.3 | J30: 48
A31: IRENA (2026) Renewable Power Generation Costs in 2025 | B31: World | C31: Global average | D31: 2020 | E31: Real 2025 USD | F31: 60.8 | G31: 40.9 | J31: 51.5
A32: IRENA (2026) Renewable Power Generation Costs in 2025 | B32: World | C32: Global average | D32: 2021 | E32: Real 2025 USD | F32: 54.4 | G32: 36.1 | J32: 56.5
... A36: IRENA (2026) Renewable Power Generation Costs in 2025 | B36: World | C36: Global average | D36: 2025 | E36: Real 2025 USD | F36: 43.5 | G36: 33 | J36: 61.7
A37: IRENA (2026) Renewable Power Generation Costs in 2025 | B37: Australia | C37: Country | D37: 2010 | E37: Real 2025 USD | F37: 490.5 | G37: 146.6
A38: IRENA (2026) Renewable Power Generation Costs in 2025 | B38: Australia | C38: Country | D38: 2011 | E38: Real 2025 USD | F38: 487.5 | G38: 125.3
A39: IRENA (2026) Renewable Power Generation Costs in 2025 | B39: Australia | C39: Country | D39: 2012 | E39: Real 2025 USD | F39: 293.7 | G39: 122.3
A40: IRENA (2026) Renewable Power Generation Costs in 2025 | B40: Australia | C40: Country | D40: 2013 | E40: Real 2025 USD | F40: 172.2 | G40: 97.4
A41: IRENA (2026) Renewable Power Generation Costs in 2025 | B41: Australia | C41: Country | D41: 2014 | E41: Real 2025 USD | F41: 141.9 | G41: 96.2
A42: IRENA (2026) Renewable Power Generation Costs in 2025 | B42: Australia | C42: Country | D42: 2015 | E42: Real 2025 USD | F42: 121.8 | G42: 82.1
A43: IRENA (2026) Renewable Power Generation Costs in 2025 | B43: Australia | C43: Country | D43: 2016 | E43: Real 2025 USD | F43: 93.4 | G43: 77.1
A44: IRENA (2026) Renewable Power Generation Costs in 2025 | B44: Australia | C44: Country | D44: 2017 | E44: Real 2025 USD | F44: 99.2 | G44: 60.1
A45: IRENA (2026) Renewable Power Generation Costs in 2025 | B45: Australia | C45: Country | D45: 2018 | E45: Real 2025 USD | F45: 83.1 | G45: 49.2
A46: IRENA (2026) Renewable Power Generation Costs in 2025 | B46: Australia | C46: Country | D46: 2019 | E46: Real 2025 USD | F46: 74.1 | G46: 46.2
A47: IRENA (2026) Renewable Power Generation Costs in 2025 | B47: Australia | C47: Country | D47: 2020 | E47: Real 2025 USD | F47: 58.5 | G47: 51.3
...

Sheet Q1 IRENA 2025 Bar
F8: Interpretation: In 2025, new utility-scale solar cost $62 per MWh in the US versus a $44 global average, and new onshore wind cost $40 versus $33 (real 2025 dollars). Even after costs fell worldwide, the US pays roughly 40% more for solar and 20% more for wind than the global average. Source: IRENA (2026), Renewable Power Generation Costs in 2025.

Sheet Q1 IRENA Solar Pivot
A1: AVERAGE of Solar PV | B1: Region
A2: Year | B2: United States | C2: World
A3: 2010 | B3: 257.4 | C3: 407.7
A4: 2011 | B4: 294 | C4: 343.9
A5: 2012 | B5: 241.7 | C5: 259.8
A6: 2013 | B6: 224.8 | C6: 202.6
A7: 2014 | B7: 170.2 | C7: 180.8
A8: 2015 | B8: 158.9 | C8: 133.7
A9: 2016 | B9: 142.8 | C9: 117.4
A10: 2017 | B10: 104.1 | C10: 93.6
A11: 2018 | B11: 83 | C11: 79.2
A12: 2019 | B12: 68.1 | C12: 68.5
A13: 2020 | B13: 65.6 | C13: 60.8
A14: 2021 | B14: 61.2 | C14: 54.4
... A18: 2025 | B18: 62 | C18: 43.5
A20: Interpretation: Between 2010 and 2025, the global average cost of new solar power fell by about 89% ($408 to $44 per MWh), and the US fell by about 76% ($257 to $62), in real 2025 dollars. Since 2020, US solar has cost more than the world average, about 40% higher in 2025. Source: IRENA (2026), Renewable Power Generation Costs in 2025.

Sheet Q1 IRENA Wind Pivot
A1: AVERAGE of Onshore wind | B1: Region
A2: Year | B2: United States | C2: World
A3: 2010 | B3: 113 | C3: 113.6
A4: 2011 | B4: 117.5 | C4: 107.7
A5: 2012 | B5: 101.3 | C5: 98.8
A6: 2013 | B6: 84.2 | C6: 99.1
A7: 2014 | B7: 67.4 | C7: 87.6
A8: 2015 | B8: 61 | C8: 76
A9: 2016 | B9: 57.4 | C9: 69.8
A10: 2017 | B10: 50.1 | C10: 64.8
A11: 2018 | B11: 46.1 | C11: 55.6
A12: 2019 | B12: 41.8 | C12: 49.3
A13: 2020 | B13: 37.2 | C13: 40.9
A14: 2021 | B14: 32.5 | C14: 36.1
... A18: 2025 | B18: 39.8 | C18: 33
A20: Interpretation: Between 2010 and 2025, the global average cost of new onshore wind fell by about 71% ($114 to $33 per MWh), and the US fell by about 65% ($113 to $40), in real 2025 dollars. The US was cheaper than the world average for most of the decade, but costs rose about a third after 2022, leaving US wind around 20% above the world average in 2025. Source: IRENA (2026), Renewable Power Generation Costs in 2025.

Sheet Q1 Lazard Pivot
F2: 83
A20: Interpretation: Between 2009 and 2025, the estimated average cost of new US power projects fell by about 84% for utility-scale solar and 55% for onshore wind, compared with a 6% decrease for gas and a 10% increase for coal (nominal dollars). On average both remained cheaper than coal and gas in 2025 ($58 and $61 per MWh, versus $78 for gas and $122 for coal), but cost data alone cannot show whether the US actually switched. 2022 was not published by Lazard.

Sheet Q1 Python
J3: Interpretation: Between 2009 and 2025, the estimated average cost of new US power projects fell by about 84% for utility-scale solar and 55% for onshore wind, compared with a 6% decrease for gas and a 10% increase for coal (nominal dollars). On average both remained cheaper than coal and gas in 2025 ($58 and $61 per MWh, versus $78 for gas and $122 for coal), but cost data alone cannot show whether the US actually switched. This Python version highlights solar and wind with thicker coloured lines, keeps coal and gas in grey, and shades 2022 because Lazard did not publish that year.
J21: Interpretation: Between 2010 and 2025, the global average cost of new solar power fell by about 89% ($408 to $44 per MWh) and onshore wind by about 71% ($114 to $33), in real 2025 dollars. Each thin grey line is one country, and almost all of them fell the same way, so the decline is global, not just a US story. In 2025, though, the US (dashed line) sits above the world average for both: $62 vs $44 for solar and $40 vs $33 for wind. Source: IRENA (2026), Renewable Power Generation Costs in 2025.

Sheet Q2 Raw Data
A1: Entity | B1: Code | C1: Year | D1: Coal | E1: Gas | F1: Hydropower | G1: Solar | H1: Wind | I1: Oil | J1: Nuclear | K1: Other renewables | L1: Bioenergy | M1: Other
A2: ASEAN (Ember) | C2: 2000 | D2: 20.073397 | E2: 43.36783 | F2: 13.3145 | G2: 0 | H2: 0 | I2: 17.224627 | J2: 0 | K2: 4.469849 | L2: 1.549794 | M2: =I2+K2+L2 -> 23.24427
A3: ASEAN (Ember) | C3: 2001 | D3: 21.294035 | E3: 47.00437 | F3: 13.411835 | G3: 0 | H3: 0 | I3: 12.646572 | J3: 0 | K3: 4.048483 | L3: 1.5947074 | M3: =I3+K3+L3 -> 18.289762
A4: ASEAN (Ember) | C4: 2002 | D4: 21.567904 | E4: 48.22826 | F4: 12.30407 | G4: 0 | H4: 0 | I4: 12.537224 | J4: 0 | K4: 3.8343453 | L4: 1.5281978 | M4: =I4+K4+L4 -> 17.899767
A5: ASEAN (Ember) | C5: 2003 | D5: 22.258347 | E5: 49.423958 | F5: 11.610299 | G5: 0 | H5: 0 | I5: 11.649574 | J5: 0 | K5: 3.4344316 | L5: 1.6233908 | M5: =I5+K5+L5 -> 16.707396
A6: ASEAN (Ember) | C6: 2004 | D6: 23.15902 | E6: 49.165344 | F6: 10.670345 | G6: 0 | H6: 0 | I6: 11.979219 | J6: 0 | K6: 3.3366222 | L6: 1.6894547 | M6: =I6+K6+L6 -> 17.005296
A7: ASEAN (Ember) | C7: 2005 | D7: 23.825285 | E7: 48.461777 | F7: 10.308411 | G7: 0 | H7: 0.0038264329 | I7: 12.562181 | J7: 0 | K7: 3.1568072 | L7: 1.6817173 | M7: =I7+K7+L7 -> 17.400705
A8: ASEAN (Ember) | C8: 2006 | D8: 25.235302 | E8: 48.005196 | F8: 11.060549 | G8: 0.0073103425 | H8: 0.0091379285 | I8: 10.994755 | J8: 0 | K8: 3.130654 | L8: 1.557103 | M8: =I8+K8+L8 -> 15.682512
A9: ASEAN (Ember) | C9: 2007 | D9: 26.89212 | E9: 47.32806 | F9: 10.924385 | G9: 0.0069087017 | H9: 0.010363053 | I9: 10.093613 | J9: 0 | K9: 2.9776504 | L9: 1.7669004 | M9: =I9+K9+L9 -> 14.838164
A10: ASEAN (Ember) | C10: 2008 | D10: 25.172195 | E10: 48.528046 | F10: 11.581892 | G10: 0.0066229547 | H10: 0.009934432 | I10: 9.80694 | J10: 0 | K10: 3.1508708 | L10: 1.7434928 | M10: =I10+K10+L10 -> 14.701304
A11: ASEAN (Ember) | C11: 2009 | D11: 26.064331 | E11: 49.445217 | F11: 11.798517 | G11: 0.006404406 | H11: 0.011207711 | I11: 7.792561 | J11: 0 | K11: 3.1413612 | L11: 1.7403973 | M11: =I11+K11+L11 -> 12.674319
A12: ASEAN (Ember) | C12: 2010 | D12: 27.296684 | E12: 47.641445 | F12: 11.657397 | G12: 0.010191306 | H12: 0.014559008 | I12: 8.578167 | J12: 0 | K12: 2.8084328 | L12: 1.9931282 | M12: =I12+K12+L12 -> 13.379728
A13: ASEAN (Ember) | C13: 2011 | D13: 29.450401 | E13: 42.545357 | F13: 13.889857 | G13: 0.01394564 | H13: 0.01812933 | I13: 9.220858 | J13: 0 | K13: 2.695692 | L13: 2.165758 | M13: =I13+K13+L13 -> 14.082308
... A27: ASEAN (Ember) | C27: 2025 | D27: 44.561813 | E27: 27.38402 | F27: 17.438406 | G27: 3.3821223 | H27: 1.4403037 | I27: 1.1081506 | J27: 0 | K27: 1.9556887 | L27: 2.729496 | M27: =I27+K27+L27 -> 5.7933353
A28: Afghanistan | B28: AFG | C28: 2000 | D28: 0 | E28: 0 | F28: 64.583336 | G28: 0 | H28: 0 | I28: 35.416668 | J28: 0 | K28: 0 | L28: 0 | M28: =I28+K28+L28 -> 35.416668
A29: Afghanistan | B29: AFG | C29: 2001 | D29: 5.7971015 | E29: 0 | F29: 72.46377 | G29: 0 | H29: 0 | I29: 21.739132 | J29: 0 | K29: 0 | L29: 0 | M29: =I29+K29+L29 -> 21.739132
A30: Afghanistan | B30: AFG | C30: 2002 | D30: 5.633803 | E30: 0 | F30: 78.873245 | G30: 0 | H30: 0 | I30: 15.492958 | J30: 0 | K30: 0 | L30: 0 | M30: =I30+K30+L30 -> 15.492958
A31: Afghanistan | B31: AFG | C31: 2003 | D31: 9.89011 | E31: 0 | F31: 69.23077 | G31: 0 | H31: 0 | I31: 20.87912 | J31: 0 | K31: 0 | L31: 0 | M31: =I31+K31+L31 -> 20.87912
A32: Afghanistan | B32: AFG | C32: 2004 | D32: 7.5949364 | E32: 0 | F32: 70.88608 | G32: 0 | H32: 0 | I32: 21.518988 | J32: 0 | K32: 0 | L32: 0 | M32: =I32+K32+L32 -> 21.518988
A33: Afghanistan | B33: AFG | C33: 2005 | D33: 7.317073 | E33: 0 | F33: 71.95122 | G33: 0 | H33: 0 | I33: 20.731709 | J33: 0 | K33: 0 | L33: 0 | M33: =I33+K33+L33 -> 20.731709
A34: Afghanistan | B34: AFG | C34: 2006 | D34: 16.666668 | E34: 0 | F34: 71.111115 | G34: 0 | H34: 0 | I34: 12.222222 | J34: 0 | K34: 0 | L34: 0 | M34: =I34+K34+L34 -> 12.222222
A35: Afghanistan | B35: AFG | C35: 2007 | D35: 14.851486 | E35: 0 | F35: 74.25742 | G35: 0 | H35: 0 | I35: 10.891089 | J35: 0 | K35: 0 | L35: 0 | M35: =I35+K35+L35 -> 10.891089
A36: Afghanistan | B36: AFG | C36: 2008 | D36: 16.666666 | E36: 0 | F36: 69.230774 | G36: 0 | H36: 0 | I36: 14.102565 | J36: 0 | K36: 0 | L36: 0 | M36: =I36+K36+L36 -> 14.102565
A37: Afghanistan | B37: AFG | C37: 2009 | D37: 6.741573 | E37: 0 | F37: 87.64045 | G37: 0 | H37: 0 | I37: 5.6179776 | J37: 0 | K37: 0 | L37: 0 | M37: =I37+K37+L37 -> 5.6179776
A38: Afghanistan | B38: AFG | C38: 2010 | D38: 6.8181815 | E38: 0 | F38: 85.22727 | G38: 0 | H38: 0 | I38: 7.9545455 | J38: 0 | K38: 0 | L38: 0 | M38: =I38+K38+L38 -> 7.9545455
A39: Afghanistan | B39: AFG | C39: 2011 | D39: 12.987014 | E39: 0 | F39: 77.92208 | G39: 0 | H39: 0 | I39: 9.090909 | J39: 0 | K39: 0 | L39: 0 | M39: =I39+K39+L39 -> 9.090909
... A52: Afghanistan | B52: AFG | C52: 2024 | D52: 3.030303 | E52: 0 | F52: 75.757576 | G52: 11.111111 | H52: 0 | I52: 10.10101 | J52: 0 | K52: 0 | L52: 0 | M52: =I52+K52+L52 -> 10.10101
A53: Africa | B53: OWID_AFR | C53: 1985 | D53: 53.869488 | E53: 10.783022 | F53: 19.093586 | G53: 0 | H53: 0 | I53: 13.242261 | J53: 2.0522358 | M53: =I53+K53+L53 -> 13.242261
A54: Africa | B54: OWID_AFR | C54: 1986 | D54: 52.600204 | E54: 10.495366 | F54: 18.93504 | G54: 0 | H54: 0 | I54: 13.766315 | J54: 3.2590466 | M54: =I54+K54+L54 -> 13.766315
A55: Africa | B55: OWID_AFR | C55: 1987 | D55: 54.316612 | E55: 11.269554 | F55: 17.50394 | G55: 0 | H55: 0 | I55: 13.802774 | J55: 2.2004604 | M55: =I55+K55+L55 -> 13.802774
A56: Africa | B56: OWID_AFR | C56: 1988 | D56: 51.6258 | E56: 11.517102 | F56: 18.149086 | G56: 0 | H56: 0 | I56: 14.430585 | J56: 3.5533884 | M56: =I56+K56+L56 -> 14.430585
A57: Africa | B57: OWID_AFR | C57: 1989 | D57: 51.267487 | E57: 12.046066 | F57: 18.352066 | G57: 0 | H57: 0 | I57: 14.132787 | J57: 3.6194615 | M57: =I57+K57+L57 -> 14.132787
A58: Africa | B58: OWID_AFR | C58: 1990 | D58: 51.65804 | E58: 13.378037 | F58: 17.960768 | G58: 0 | H58: 0 | I58: 13.472092 | J58: 2.6504488 | M58: =I58+K58+L58 -> 13.472092
A59: Africa | B59: OWID_AFR | C59: 1991 | D59: 50.727135 | E59: 14.040883 | F59: 18.67074 | G59: 0 | H59: 0 | I59: 12.936341 | J59: 2.8148565 | M59: =I59+K59+L59 -> 12.936341
A60: Africa | B60: OWID_AFR | C60: 1992 | D60: 50.452843 | E60: 15.415956 | F60: 17.647255 | G60: 0 | H60: 0 | I60: 12.983688 | J60: 2.8328185 | M60: =I60+K60+L60 -> 12.983688
A61: Africa | B61: OWID_AFR | C61: 1993 | D61: 51.893387 | E61: 16.260033 | F61: 16.716867 | G61: 0 | H61: 0.00058984227 | I61: 12.313243 | J61: 2.1396527 | M61: =I61+K61+L61 -> 12.313243
A62: Africa | B62: OWID_AFR | C62: 1994 | D62: 51.174583 | E62: 17.675919 | F62: 16.393536 | G62: 0 | H62: 0.0015369994 | I62: 11.322014 | J62: 2.7600522 | M62: =I62+K62+L62 -> 11.322014
A63: Africa | B63: OWID_AFR | C63: 1995 | D63: 51.527397 | E63: 18.283823 | F63: 16.4741 | G63: 0 | H63: 0.0017370101 | I63: 9.96238 | J63: 3.115865 | M63: =I63+K63+L63 -> 9.96238
A64: Africa | B64: OWID_AFR | C64: 1996 | D64: 51.62797 | E64: 18.315662 | F64: 16.30236 | G64: 0 | H64: 0.0018579572 | I64: 9.758218 | J64: 3.0813303 | M64: =I64+K64+L64 -> 9.758218
... A67: Africa | B67: OWID_AFR | C67: 1999 | D67: 47.730385 | E67: 20.56667 | F67: 16.88618 | G67: 0 | H67: 0.0047301394 | I67: 10.718711 | J67: 3.066707 | M67: =I67+K67+L67 -> 10.718711
...

Sheet Q2 Data Sources | Notes 
A1: Q2 data sources and notes
A4: DATA SOURCE
A6: Our World in Data - Share of electricity generation by source (2000-2025)
A7: Link to Dataset
A9: THINKING
A10: Other = Oil + Bionergy + Other Renewables
A11: Wind + Solar = Wind share + Solar share
A12: Values Represent percentages of electricity generation, not total energy consumption or absolute production
A13: Charts use U.S. and World Data for 2000, 2005, 2010, 2015, 2020, 2025
A15: ADDITIONAL ANALYSIS
A17: Countries analyzed: 88 (2025 Data Available)
A18: Median Country's wind and solar share: 13.09%
... A22: The Global electrixity is generation-weighted, meaning countries that generate more electricity have a greater influence on the world figure.

Sheet Q2 Electricity Mix
A2: Year | B2: Other | C2: Nuclear | D2: Gas | E2: Hydropower | F2: Coal | G2: Wind + Solar
A3: 2000 | B3: 5.0193313 | C3: 19.828253 | D3: 16.175009 | E3: 7.1021276 | F3: 51.715366 | G3: 0.15991163
A4: 2005 | B4: 4.8835312 | C4: 19.38022 | D4: 18.859032 | E4: 6.5368195 | F4: 49.885376 | G4: 0.4550197
A5: 2010 | B5: 2.9514286 | C5: 19.615501 | D5: 24.008615 | E5: 6.1911454 | F5: 44.903183 | G5: 2.3301265
A6: 2015 | B6: 3.1143562 | C6: 19.519636 | D6: 32.6514 | E6: 5.9743047 | F6: 33.114674 | G6: 5.625626
A7: 2020 | B7: 2.6496471 | C7: 19.536108 | D7: 40.17061 | E7: 6.924006 | F7: 19.128262 | G7: 11.591372
A8: 2025 | B8: 2.1153637 | C8: 17.363197 | D8: 39.987255 | E8: 5.3475933 | F8: 16.309387 | G8: 18.877204
K44: Interpretation: This chart demonstrates that although the US made significant progress toward renewable electricity, much of its transistion away from coal involved switching to another fossil fuel, Natural Gas.

Sheet Q2 Python Chart
A35: Interpetation: Beyond the global average only being 1.6% below the US our analyis reveals a larger difference when comparing the US to indivisual countries. Among the 88 countries with availble 2025 data, the median rather then the average was 13.1% comapared to the US at 18.9% around a 5.8% difference. The US exceeded approximately 60% of countries in our sample and we can assume if there were more countries that participated in this dataset that number could be much larger. This makes me ask, Is the worldwide transistion being driven disproportiantly by countries that generate larger amounts of electricity? Because the analysis covers only 88 countries, additional country-level data would be needed to determine how true/false these findings are.

Sheet Q3 Raw Data
A1: Country | B1: ISO_Code | C1: Year | D1: Coal_pct | E1: Gas_pct | F1: Oil_pct | G1: Nuclear_pct | H1: Hydro_pct | I1: Solar_pct | J1: Wind_pct | K1: Bioenergy_pct | L1: Other_Renewables_pct | M1: Fossil_Fuels_Total_pct | N1: Low_Carbon_Total_pct | O1: Electricity_Generation_TWh | P1: Solar_Wind_pct | Q1: Other_pct | R1: Large_2024
A2: Afghanistan | B2: AFG | C2: 2015 | D2: 8.47 | E2: 0 | F2: 4.24 | G2: 0 | H2: 84.75 | I2: 2.54 | J2: 0 | K2: 0 | L2: 0 | M2: 12.71 | N2: 87.29 | O2: 1.18 | P2: 2.54 | Q2: 0 | R2: No
A3: Afghanistan | B3: AFG | C3: 2024 | D3: 3.03 | E3: 0 | F3: 10.1 | G3: 0 | H3: 75.76 | I3: 11.11 | J3: 0 | K3: 0 | L3: 0 | M3: 13.13 | N3: 86.87 | O3: 0.99 | P3: 11.11 | Q3: 0 | R3: No
A4: Albania | B4: ALB | C4: 2015 | D4: 0 | E4: 0 | F4: 0 | G4: 0 | H4: 100 | I4: 0 | J4: 0 | K4: 0 | L4: 0 | M4: 0 | N4: 100 | O4: 5.89 | P4: 0 | Q4: 0 | R4: No
A5: Albania | B5: ALB | C5: 2024 | D5: 0 | E5: 0 | F5: 0 | G5: 0 | H5: 95.92 | I5: 4.08 | J5: 0 | K5: 0 | L5: 0 | M5: 0 | N5: 100 | O5: 8.34 | P5: 4.08 | Q5: 0 | R5: No
A6: Algeria | B6: DZA | C6: 2015 | D6: 0 | E6: 98.3 | F6: 1.38 | G6: 0 | H6: 0.2 | I6: 0.09 | J6: 0.03 | K6: 0 | L6: 0 | M6: 99.68 | N6: 0.32 | O6: 68.84 | P6: 0.12 | Q6: 0 | R6: Yes
A7: Algeria | B7: DZA | C7: 2024 | D7: 0 | E7: 98.59 | F7: 0.34 | G7: 0 | H7: 0.02 | I7: 1.03 | J7: 0.02 | K7: 0 | L7: 0 | M7: 98.93 | N7: 1.07 | O7: 96.36 | P7: 1.05 | Q7: 0 | R7: Yes
A8: American Samoa | B8: ASM | C8: 2015 | D8: 0 | E8: 0 | F8: 100 | G8: 0 | H8: 0 | I8: 0 | J8: 0 | K8: 0 | L8: 0 | M8: 100 | N8: 0 | O8: 0.16 | P8: 0 | Q8: 0 | R8: No
A9: American Samoa | B9: ASM | C9: 2024 | D9: 0 | E9: 0 | F9: 94.44 | G9: 0 | H9: 0 | I9: 5.56 | J9: 0 | K9: 0 | L9: 0 | M9: 94.44 | N9: 5.56 | O9: 0.18 | P9: 5.56 | Q9: 0 | R9: No
A10: Angola | B10: AGO | C10: 2015 | D10: 0 | E10: 0 | F10: 45.4 | G10: 0 | H10: 53.99 | I10: 0.2 | J10: 0 | K10: 0.41 | L10: 0 | M10: 45.4 | N10: 54.6 | O10: 9.78 | P10: 0.2 | Q10: 0.41 | R10: No
A11: Angola | B11: AGO | C11: 2024 | D11: 0 | E11: 8.98 | F11: 17.32 | G11: 0 | H11: 70.56 | I11: 2.82 | J11: 0 | K11: 0.32 | L11: 0 | M11: 26.3 | N11: 73.7 | O11: 15.59 | P11: 2.82 | Q11: 0.32 | R11: No
A12: Antigua and Barbuda | B12: ATG | C12: 2015 | D12: 0 | E12: 0 | F12: 97.14 | G12: 0 | H12: 0 | I12: 2.86 | J12: 0 | K12: 0 | L12: 0 | M12: 97.14 | N12: 2.86 | O12: 0.35 | P12: 2.86 | Q12: 0 | R12: No
A13: Antigua and Barbuda | B13: ATG | C13: 2024 | D13: 0 | E13: 0 | F13: 91.89 | G13: 0 | H13: 0 | I13: 8.11 | J13: 0 | K13: 0 | L13: 0 | M13: 91.89 | N13: 8.11 | O13: 0.37 | P13: 8.11 | Q13: 0 | R13: No
... A237: Mongolia | B237: MNG | C237: 2024 | D237: 84.69 | E237: 0 | F237: 6.46 | G237: 0 | H237: 0.68 | I237: 2.38 | J237: 5.78 | K237: 0 | L237: 0 | M237: 91.16 | N237: 8.84 | O237: 8.82 | P237: 8.16 | Q237: 0 | R237: No
A238: Montenegro | B238: MNE | C238: 2015 | D238: 50.33 | E238: 0 | F238: 0 | G238: 0 | H238: 49.67 | I238: 0 | K238: 0 | L238: 0 | M238: 50.33 | N238: 49.67 | O238: 3 | Q238: 0 | R238: No
A239: Montenegro | B239: MNE | C239: 2024 | D239: 40.51 | E239: 0 | F239: 0 | G239: 0 | H239: 50.14 | I239: 1.7 | J239: 7.65 | K239: 0 | L239: 0 | M239: 40.51 | N239: 59.49 | O239: 3.53 | P239: 9.35 | Q239: 0 | R239: No
A240: Montserrat | B240: MSR | C240: 2015 | D240: 0 | E240: 0 | F240: 100 | G240: 0 | H240: 0 | I240: 0 | J240: 0 | K240: 0 | L240: 0 | M240: 100 | N240: 0 | O240: 0.01 | P240: 0 | Q240: 0 | R240: No
A241: Montserrat | B241: MSR | C241: 2024 | D241: 0 | E241: 0 | F241: 100 | G241: 0 | H241: 0 | I241: 0 | J241: 0 | K241: 0 | L241: 0 | M241: 100 | N241: 0 | O241: 0.01 | P241: 0 | Q241: 0 | R241: No
A242: Morocco | B242: MAR | C242: 2015 | D242: 57.2 | E242: 19.32 | F242: 7.39 | G242: 0 | H242: 7.62 | I242: 0 | J242: 8.43 | K242: 0.03 | L242: 0 | M242: 83.92 | N242: 16.08 | O242: 29.91 | P242: 8.43 | Q242: 0.03 | R242: Yes
A243: Morocco | B243: MAR | C243: 2024 | D243: 61.75 | E243: 10.21 | F243: 3.63 | G243: 0 | H243: 1.91 | I243: 5.68 | J243: 16.72 | K243: 0.09 | L243: 0 | M243: 75.59 | N243: 24.41 | O243: 42.4 | P243: 22.41 | Q243: 0.09 | R243: Yes
A244: Mozambique | B244: MOZ | C244: 2015 | D244: 0 | E244: 6.91 | F244: 0.11 | G244: 0 | H244: 92.98 | I244: 0 | J244: 0 | K244: 0 | L244: 0 | M244: 7.02 | N244: 92.98 | O244: 18.38 | P244: 0 | Q244: 0 | R244: No
A245: Mozambique | B245: MOZ | C245: 2024 | D245: 0 | E245: 15.82 | F245: 0.76 | G245: 0 | H245: 82.36 | I245: 0.4 | J245: 0 | K245: 0.66 | L245: 0 | M245: 16.57 | N245: 83.43 | O245: 19.79 | P245: 0.4 | Q245: 0.66 | R245: No
A246: Myanmar | B246: MMR | C246: 2015 | D246: 1.73 | E246: 38.46 | F246: 0.31 | G246: 0 | H246: 58.02 | I246: 0.19 | J246: 0 | K246: 1.3 | L246: 0 | M246: 40.49 | N246: 59.51 | O246: 16.2 | P246: 0.19 | Q246: 1.3 | R246: Yes
A247: Myanmar | B247: MMR | C247: 2024 | D247: 5.53 | E247: 46.06 | F247: 0.55 | G247: 0 | H247: 46.06 | I247: 0.55 | J247: 0 | K247: 1.24 | L247: 0 | M247: 52.14 | N247: 47.86 | O247: 21.71 | P247: 0.55 | Q247: 1.24 | R247: Yes
A248: Namibia | B248: NAM | C248: 2015 | D248: 0.63 | E248: 0 | F248: 1.9 | G248: 0 | H248: 94.94 | I248: 2.53 | J248: 0 | K248: 0 | L248: 0 | M248: 2.53 | N248: 97.47 | O248: 1.58 | P248: 2.53 | Q248: 0 | R248: No
A249: Namibia | B249: NAM | C249: 2024 | D249: 2.44 | E249: 0 | F249: 0 | G249: 0 | H249: 60.98 | I249: 35.37 | J249: 1.22 | K249: 0 | L249: 0 | M249: 2.44 | N249: 97.56 | O249: 1.64 | P249: 36.59 | Q249: 0 | R249: No
A250: Nauru | B250: NRU | C250: 2015 | D250: 0 | E250: 0 | F250: 100 | G250: 0 | H250: 0 | I250: 0 | J250: 0 | K250: 0 | L250: 0 | M250: 100 | N250: 0 | O250: 0.03 | P250: 0 | Q250: 0 | R250: No
... A398: Zimbabwe | B398: ZWE | C398: 2024 | D398: 42.88 | E398: 0 | F398: 0 | G398: 0 | H398: 55.56 | I398: 0.39 | J398: 0 | K398: 1.17 | L398: 0 | M398: 42.88 | N398: 57.12 | O398: 10.26 | P398: 0.39 | Q398: 1.17 | R398: No

Sheet Q3 Pivot
D2: Fossil Change | E2: Rank | G2: World_Change
D3: =C3-B3 -> -0.75 | E3: =RANK(D3,$D$3:$D$85,1) -> 66 | G3: =59.09-66.48 -> -7.39 | H3: World fossil share, 2015 vs 2024 (Our World in Data)
D4: =C4-B4 -> -12.72 | E4: =RANK(D4,$D$3:$D$85,1) -> 24
D5: =C5-B5 -> -20.98 | E5: =RANK(D5,$D$3:$D$85,1) -> 12
D6: =C6-B6 -> -9.19 | E6: =RANK(D6,$D$3:$D$85,1) -> 34
D7: =C7-B7 -> -4.79 | E7: =RANK(D7,$D$3:$D$85,1) -> 50
D8: =C8-B8 -> -0.22 | E8: =RANK(D8,$D$3:$D$85,1) -> 70
D9: =C9-B9 -> -0.54 | E9: =RANK(D9,$D$3:$D$85,1) -> 69
D10: =C10-B10 -> -36.32 | E10: =RANK(D10,$D$3:$D$85,1) -> 3
D11: =C11-B11 -> -17.11 | E11: =RANK(D11,$D$3:$D$85,1) -> 17
D12: =C12-B12 -> -12.71 | E12: =RANK(D12,$D$3:$D$85,1) -> 25
D13: =C13-B13 -> -21.58 | E13: =RANK(D13,$D$3:$D$85,1) -> 9
D14: =C14-B14 -> 1.44 | E14: =RANK(D14,$D$3:$D$85,1) -> 75
D15: =C15-B15 -> -26.84 | E15: =RANK(D15,$D$3:$D$85,1) -> 6
... D85: =C85-B85 -> -7.5 | E85: =RANK(D85,$D$3:$D$85,1) -> 38

Sheet Q3 Table
A1: Country | B1: 2015 | C1: 2024 | D1: Fossil Change | E1: Rank
A2: Portugal | B2: 52.37 | C2: 14.81 | D2: -37.56 | E2: 1
A3: Netherlands | B3: 83.7 | C3: 46.34 | D3: -37.36 | E3: 2
A4: Belarus | B4: 99 | C4: 62.68 | D4: -36.32 | E4: 3
A5: Venezuela | B5: 41.19 | C5: 8.86 | D5: -32.33 | E5: 4
A6: United Arab Emirates | B6: 99.76 | C6: 68.27 | D6: -31.49 | E6: 5
A7: Chile | B7: 56.8 | C7: 29.96 | D7: -26.84 | E7: 6
A8: Denmark | B8: 34.23 | C8: 10.81 | D8: -23.42 | E8: 7
A9: Jordan | B9: 98.79 | C9: 75.92 | D9: -22.87 | E9: 8
A10: Bulgaria | B10: 50.46 | C10: 28.88 | D10: -21.58 | E10: 9
A11: Ecuador | B11: 48.9 | C11: 27.56 | D11: -21.34 | E11: 10
A12: Spain | B12: 44.34 | C12: 23.25 | D12: -21.09 | E12: 11
A13: Australia | B13: 85.9 | C13: 64.92 | D13: -20.98 | E13: 12
... A84: Ghana | B84: 50.09 | C84: 63.78 | D84: 13.69 | E84: 83

Sheet Q3 Replacements
L3: Fossil | M3: Solar+Wind | N3: Hydro | O3: Nuclear | P3: Other.
L4: =G4+B4 -> -0.75 | M4: {=H4:H86+C4:C86} -> 0.93 | N4: {=I4:I86+D4:D86} -> -0.18 | O4: {=J4:J86+E4:E86} -> 0 | P4: {=K4:K86+F4:F86} -> 0
L5: =G5+B5 -> -12.72 | M5: 12.8 | N5: -2.79 | O5: 2.01 | P5: 0.7
L6: =G6+B6 -> -20.98 | M6: 22.35 | N6: -0.99 | O6: 0 | P6: -0.39
L7: =G7+B7 -> -9.19 | M7: 12.66 | N7: -1.9 | O7: 0 | P7: -1.58
L8: =G8+B8 -> -4.79 | M8: 0.61 | N8: 4.19 | O8: 0 | P8: -0.01
L9: =G9+B9 -> -0.22 | M9: 0.22 | N9: 0 | O9: 0 | P9: 0
L10: =G10+B10 -> -0.54 | M10: 0.85 | N10: -0.31 | O10: 0 | P10: 0
L11: =G11+B11 -> -36.32 | M11: 0.88 | N11: 0.55 | O11: 34.24 | P11: 0.64
L12: =G12+B12 -> -17.11 | M12: 17.15 | N12: 0.25 | O12: 2.97 | P12: -3.27
L13: =G13+B13 -> -12.71 | M13: 20.38 | N13: -6.48 | O13: -0.41 | P13: -0.77
L14: =G14+B14 -> -21.58 | M14: 12.34 | N14: -4.32 | O14: 9.63 | P14: 3.94
L15: =G15+B15 -> 1.44 | M15: 4.31 | N15: -3.91 | O15: -1.87 | P15: 0.03
L16: =G16+B16 -> -26.84 | M16: 30.08 | N16: -1.9 | O16: 0 | P16: -1.34
... L86: =G86+B86 -> -7.5 | M86: 12.64 | N86: -5.44 | O86: 0 | P86: 0.3

Sheet Q3 G20
A1: Country | B1: Fossil_Change
A2: Australia | B2: =VLOOKUP(A2,'Q3 Table'!A:D,4,FALSE) -> -20.98
A3: United Kingdom | B3: =VLOOKUP(A3,'Q3 Table'!A:D,4,FALSE) -> -19.57
A4: Japan | B4: =VLOOKUP(A4,'Q3 Table'!A:D,4,FALSE) -> -15.9
A5: Germany | B5: =VLOOKUP(A5,'Q3 Table'!A:D,4,FALSE) -> -14.84
A6: Turkey | B6: =VLOOKUP(A6,'Q3 Table'!A:D,4,FALSE) -> -13.65
A7: Argentina | B7: =VLOOKUP(A7,'Q3 Table'!A:D,4,FALSE) -> -12.72
A8: Brazil | B8: =VLOOKUP(A8,'Q3 Table'!A:D,4,FALSE) -> -12.71
A9: China | B9: =VLOOKUP(A9,'Q3 Table'!A:D,4,FALSE) -> -11.25
A10: Italy | B10: =VLOOKUP(A10,'Q3 Table'!A:D,4,FALSE) -> -11.24
A11: United States | B11: =VLOOKUP(A11,'Q3 Table'!A:D,4,FALSE) -> -8.72
A12: South Africa | B12: =VLOOKUP(A12,'Q3 Table'!A:D,4,FALSE) -> -8.16
A13: South Korea | B13: =VLOOKUP(A13,'Q3 Table'!A:D,4,FALSE) -> -7.04
... A20: Canada | B20: =VLOOKUP(A20,'Q3 Table'!A:D,4,FALSE) -> 1.44
A26: Interpretation: Among 83 countries generating at least 20 TWh, Portugal (−37.6 percentage points) and the Netherlands (−37.4) cut the fossil fuel share of their electricity the most between 2015 and 2024. They did not all switch the same way. The Netherlands, Chile and Jordan replaced fossil power mainly with solar and wind; Belarus and the UAE with new nuclear plants; and Venezuela and Ecuador with hydro (Venezuela's drop reflects an economic crisis rather than a policy shift). The US (−8.7) and the world (−7.4) also switched mainly through solar and wind, but at about a quarter of the leaders' pace. Cheap solar and wind are the most common route away from fossil fuels, but not the only one. Source: Our World in Data (Ember; Energy Institute).

Sheet Python Graph
G2: Python
A23: Interpretation: Between 2015 and 2024, the US cut the fossil fuel share of its electricity by 8.7 percentage points (from 66.9% to 58.1%), ranking 10th of 19 G20 countries. That is slightly faster than the world average (−7.4), but well behind Australia (−21.0), the United Kingdom (−19.6), Japan (−15.9) and Germany (−14.8). Canada is the only G20 country whose fossil share rose (+1.4), though from a low starting point (21% to 22%), as most of its power already comes from hydro. Even though clean power is now cheaper than fossil power (Q1), the US is in the middle of the pack, while comparable large economies have cut twice as fast. Source: Our World in Data (Ember; Energy Institute).
